<?xml version="1.0"?>
<robot name="mbot">

	<link name="base_link">
        <visual>
            <origin xyz="0 0 0" rpy="0 0 0" />
            <geometry>
                <cylinder length="0.005" radius="0.16"/>
            </geometry>
            <material name="yellow">
                <color rgba="1 0.4 0 1"/>
            </material>
        </visual>
    </link>
	
	<link name="left_wheel_link">
		<visual>
			<origin xyz="0 0 0" rpy="1.5707 0 0" />
			<geometry>
				<cylinder radius="0.032" length="0.025" />
			</geometry>
			<material name="white">
				<color rgba="1 1 1 0.9" />
			</material>
		</visual>
	</link>
	<joint name="left_wheel_joint" type="continuous">
		<origin xyz="0.09 0.12 -0.01" rpy="0 0 0" />
		<parent link="base_link" />
		<child link="left_wheel_link" />
		<axis xyz="0 1 0" />
	</joint>

	<link name="right_wheel_link">
		<visual>
			<origin xyz="0 0 0" rpy="1.5707 0 0" />
			<geometry>
				<cylinder radius="0.032" length="0.025" />
			</geometry>
			<material name="white">
				<color rgba="1 1 1 0.9" />
			</material>
		</visual>
	</link>
	<joint name="right_wheel_joint" type="continuous">
		<origin xyz="0.09 -0.12 -0.01" rpy="0 0 0" />
		<parent link="base_link" />
		<child link="right_wheel_link" />
		<axis xyz="0 1 0" />
	</joint>

	<link name="back_caster_link">
		<visual>
			<origin xyz="0 0 0" rpy="0 0 0" />
			<geometry>
				<sphere radius="0.022" />
			</geometry>
			<material name="black">
				<color rgba="0 0 0 0.95" />
			</material>
		</visual>
	</link>
	<joint name="back_caster_joint" type="continuous">
		<origin xyz="-0.12 0 -0.018" rpy="0 0 0" />
		<parent link="base_link" />
		<child link="back_caster_link" />
		<axis xyz="0 1 0" />
	</joint>

</robot>
